Workbook

Sheet IO List
I1: BOOL | J1: Input | K1: GVL
A2: Note: Inputs are addressed to M area to allow writing via Codesys OPC-UA server. | I2: INT | J2: Output | K2: IOs
A3: Name | B3: List | C3: Address | D3: Type | E3: Direction | F3: Comment | G3: Check | I3: - | J3: - | K3: -
A4: SOP004_A1_4 | C4: MW0 | F4: 16 DI Card, Input 0-16
A5: SOP700_S1 | B5: IOs | C5: MX0.0 | D5: BOOL | E5: Input | F5: Control Voltage On
A6: SOP700_S2 | B6: GVL | C6: MX0.1 | D6: BOOL | E6: Input | F6: Control Voltage Off (NC)
A7: SOP700_S3 | B7: GVL | C7: MX0.2 | D7: BOOL | E7: Input | F7: Manual/Auto. True=Automatic. False=Manual
A8: //Reserved | B8: - | C8: MX0.3 | D8: - | E8: -
A9: SOP700_S5 | B9: GVL | C9: MX0.4 | D9: BOOL | E9: Input | F9: Cycle Start
A10: SOP700_S6 | B10: GVL | C10: MX0.5 | D10: BOOL | E10: Input | F10: Cycle Stop
A11: SOP700_S11 | B11: GVL | C11: MX0.6 | D11: BOOL | E11: Input | F11: Entry Request
A12: SOP700_S8 | B12: GVL | C12: MX0.7 | D12: BOOL | E12: Input | F12: Reset Alarm
A13: //Reserved | B13: - | C13: MX1.0 | D13: - | E13: -
A14: SOP700_S7 | B14: GVL | C14: MX1.1 | D14: BOOL | E14: Input | F14: Halt (NC)
A15: SOP700_NS1 | B15: IOs | C15: MX1.2 | D15: BOOL | E15: Input | F15: Emergency Stop (NC)
A16: SOP750_NS1 | B16: GVL | C16: MX1.3 | D16: BOOL | E16: Input | F16: Emergency Stop (NC)
A17: SOP720_HMI_NS1 | B17: IOs | C17: MX1.4 | D17: BOOL | E17: Input | F17: Emergency Stop (NC)
A18: SOP723_HMI_NS1 | B18: IOs | C18: MX1.5 | D18: BOOL | E18: Input | F18: Emergency Stop (NC)
A19: //Reserved | B19: - | C19: MX1.6 | D19: - | E19: -
A20: //Reserved | B20: - | C20: MX1.7 | D20: - | E20: -
A21: SOP004_A1_5 | C21: MW1 | F21: 16 DI Card, Input 0-16
A22: SOP750_FQ1 | B22: IOs | C22: MX2.0 | D22: BOOL | E22: Input | F22: Supply Power Line Circuit Breaker
A23: SOP751_FQ1 | B23: IOs | C23: MX2.1 | D23: BOOL | E23: Input | F23: Power Suply Prim. Protection
A24: SOP751_F10 | B24: IOs | C24: MX2.2 | D24: BOOL | E24: Input | F24: Power Suply Sec. Protection
A25: SOP751_F11 | B25: IOs | C25: MX2.3 | D25: BOOL | E25: Input | F25: PLC Input Protection
A26: SOP751_F12 | B26: IOs | C26: MX2.4 | D26: BOOL | E26: Input | F26: PLC Output Protection
A27: SOP751_F13 | B27: IOs | C27: MX2.5 | D27: BOOL | E27: Input | F27: Safety Circuit Protection
A28: SOP750_K1 | B28: IOs | C28: MX2.6 | D28: BOOL | E28: Input | F28: Safety Circuit OK
A29: SOP750_B1 | B29: IOs | C29: MX2.7 | D29: BOOL | E29: Input | F29: Pneumatic Pressure OK
A30: SOP750_K7 | B30: GVL | C30: MX3.0 | D30: BOOL | E30: Input | F30: Safety Gate open
A31: SOP750_K8 | B31: IOs | C31: MX3.1 | D31: BOOL | E31: Input | F31: Gate Unlock Confirmation
A32: SOP750_B2 | B32: IOs | C32: MX3.2 | D32: BOOL | E32: Input | F32: Gate Closed Sensor
A33: SOP750_B3 | B33: IOs | C33: MX3.3 | D33: BOOL | E33: Input | F33: Safety Mat Activated
... A35: SOP740_ProductPlaced | B35: IOs | C35: MX3.5 | D35: BOOL | E35: Input | F35: The robot has finished
A36: //Reserved | B36: - | C36: MX3.6 | D36: - | E36: -
A37: //Reserved | B37: - | C37: MX3.7 | D37: - | E37: -
A38: SOP004_A1_6 | C38: MW2 | F38: 16 DI Card, Input 0-16
A39: SOP710_FQ1 | B39: IOs | C39: MX4.0 | D39: BOOL | E39: Input | F39: Motor Protection Tripped (NC)
A40: SOP710_B1 | B40: IOs | C40: MX4.1 | D40: BOOL | E40: Input | F40: Conveyor Sensor
A41: SOP711_FQ1 | B41: IOs | C41: MX4.2 | D41: BOOL | E41: Input | F41: Motor Protection Tripped (NC)
...

Sheet CoDeSysIOs
A1: Autogenerated CoDeSys IOs List
G2: Colums used for
B3: //Name | C3: Address | D3: Type | E3: Comment | G3: RobotStudio configuration
B4: =IF('IO List'!B4="IOs",CONCATENATE('IO List'!A4),"") | C4: =IF('IO List'!B4="IOs",CONCATENATE("AT %",'IO List'!C4),"") | D4: =IF('IO List'!B4="IOs",CONCATENATE(": ",'IO List'!D4,";"),"") | E4: =IF('IO List'!B4="IOs",CONCATENATE("// ",'IO List'!F4),"") | G4: =IF(D4=": BOOL;","Digital","Group") -> Group | H4: =IF('IO List'!E4="Input","Write","Read") -> Read
B5: =IF('IO List'!B5="IOs",CONCATENATE('IO List'!A5),"") -> SOP700_S1 | C5: =IF('IO List'!B5="IOs",CONCATENATE("AT %",'IO List'!C5),"") -> AT %MX0.0 | D5: =IF('IO List'!B5="IOs",CONCATENATE(": ",'IO List'!D5,";"),"") -> : BOOL; | E5: =IF('IO List'!B5="IOs",CONCATENATE("// ",'IO List'!F5),"") -> // Control Voltage On | G5: =IF(D5=": BOOL;","Digital","Group") -> Digital | H5: =IF('IO List'!E5="Input","Write","Read") -> Write
B6: =IF('IO List'!B6="IOs",CONCATENATE('IO List'!A6),"") | C6: =IF('IO List'!B6="IOs",CONCATENATE("AT %",'IO List'!C6),"") | D6: =IF('IO List'!B6="IOs",CONCATENATE(": ",'IO List'!D6,";"),"") | E6: =IF('IO List'!B6="IOs",CONCATENATE("// ",'IO List'!F6),"") | G6: =IF(D6=": BOOL;","Digital","Group") -> Group | H6: =IF('IO List'!E6="Input","Write","Read") -> Write
B7: =IF('IO List'!B7="IOs",CONCATENATE('IO List'!A7),"") | C7: =IF('IO List'!B7="IOs",CONCATENATE("AT %",'IO List'!C7),"") | D7: =IF('IO List'!B7="IOs",CONCATENATE(": ",'IO List'!D7,";"),"") | E7: =IF('IO List'!B7="IOs",CONCATENATE("// ",'IO List'!F7),"") | G7: =IF(D7=": BOOL;","Digital","Group") -> Group | H7: =IF('IO List'!E7="Input","Write","Read") -> Write
B8: =IF('IO List'!B8="IOs",CONCATENATE('IO List'!A8),"") | C8: =IF('IO List'!B8="IOs",CONCATENATE("AT %",'IO List'!C8),"") | D8: =IF('IO List'!B8="IOs",CONCATENATE(": ",'IO List'!D8,";"),"") | E8: =IF('IO List'!B8="IOs",CONCATENATE("// ",'IO List'!F8),"") | G8: =IF(D8=": BOOL;","Digital","Group") -> Group | H8: =IF('IO List'!E8="Input","Write","Read") -> Read
B9: =IF('IO List'!B9="IOs",CONCATENATE('IO List'!A9),"") | C9: =IF('IO List'!B9="IOs",CONCATENATE("AT %",'IO List'!C9),"") | D9: =IF('IO List'!B9="IOs",CONCATENATE(": ",'IO List'!D9,";"),"") | E9: =IF('IO List'!B9="IOs",CONCATENATE("// ",'IO List'!F9),"") | G9: =IF(D9=": BOOL;","Digital","Group") -> Group | H9: =IF('IO List'!E9="Input","Write","Read") -> Write
B10: =IF('IO List'!B10="IOs",CONCATENATE('IO List'!A10),"") | C10: =IF('IO List'!B10="IOs",CONCATENATE("AT %",'IO List'!C10),"") | D10: =IF('IO List'!B10="IOs",CONCATENATE(": ",'IO List'!D10,";"),"") | E10: =IF('IO List'!B10="IOs",CONCATENATE("// ",'IO List'!F10),"") | G10: =IF(D10=": BOOL;","Digital","Group") -> Group | H10: =IF('IO List'!E10="Input","Write","Read") -> Write
B11: =IF('IO List'!B11="IOs",CONCATENATE('IO List'!A11),"") | C11: =IF('IO List'!B11="IOs",CONCATENATE("AT %",'IO List'!C11),"") | D11: =IF('IO List'!B11="IOs",CONCATENATE(": ",'IO List'!D11,";"),"") | E11: =IF('IO List'!B11="IOs",CONCATENATE("// ",'IO List'!F11),"") | G11: =IF(D11=": BOOL;","Digital","Group") -> Group | H11: =IF('IO List'!E11="Input","Write","Read") -> Write
B12: =IF('IO List'!B12="IOs",CONCATENATE('IO List'!A12),"") | C12: =IF('IO List'!B12="IOs",CONCATENATE("AT %",'IO List'!C12),"") | D12: =IF('IO List'!B12="IOs",CONCATENATE(": ",'IO List'!D12,";"),"") | E12: =IF('IO List'!B12="IOs",CONCATENATE("// ",'IO List'!F12),"") | G12: =IF(D12=": BOOL;","Digital","Group") -> Group | H12: =IF('IO List'!E12="Input","Write","Read") -> Write
B13: =IF('IO List'!B13="IOs",CONCATENATE('IO List'!A13),"") | C13: =IF('IO List'!B13="IOs",CONCATENATE("AT %",'IO List'!C13),"") | D13: =IF('IO List'!B13="IOs",CONCATENATE(": ",'IO List'!D13,";"),"") | E13: =IF('IO List'!B13="IOs",CONCATENATE("// ",'IO List'!F13),"") | G13: =IF(D13=": BOOL;","Digital","Group") -> Group | H13: =IF('IO List'!E13="Input","Write","Read") -> Read
B14: =IF('IO List'!B14="IOs",CONCATENATE('IO List'!A14),"") | C14: =IF('IO List'!B14="IOs",CONCATENATE("AT %",'IO List'!C14),"") | D14: =IF('IO List'!B14="IOs",CONCATENATE(": ",'IO List'!D14,";"),"") | E14: =IF('IO List'!B14="IOs",CONCATENATE("// ",'IO List'!F14),"") | G14: =IF(D14=": BOOL;","Digital","Group") -> Group | H14: =IF('IO List'!E14="Input","Write","Read") -> Write
B15: =IF('IO List'!B15="IOs",CONCATENATE('IO List'!A15),"") -> SOP700_NS1 | C15: =IF('IO List'!B15="IOs",CONCATENATE("AT %",'IO List'!C15),"") -> AT %MX1.2 | D15: =IF('IO List'!B15="IOs",CONCATENATE(": ",'IO List'!D15,";"),"") -> : BOOL; | E15: =IF('IO List'!B15="IOs",CONCATENATE("// ",'IO List'!F15),"") -> // Emergency Stop (NC) | G15: =IF(D15=": BOOL;","Digital","Group") -> Digital | H15: =IF('IO List'!E15="Input","Write","Read") -> Write
... B287: =IF('IO List'!B287="IOs",CONCATENATE('IO List'!A287),"") | C287: =IF('IO List'!B287="IOs",CONCATENATE("AT %",'IO List'!C287),"") | D287: =IF('IO List'!B287="IOs",CONCATENATE(": ",'IO List'!D287,";"),"") | E287: =IF('IO List'!B287="IOs",CONCATENATE("// ",'IO List'!F287),"") | G287: =IF(D287=": BOOL;","Digital","Group") -> Group | H287: =IF('IO List'!E287="Input","Write","Read") -> Read

Sheet CoDeSysGVL
A1: Autogenerated CoDeSys GVL List
B3: //Name | C3: Address | D3: Type | E3: Comment
B4: =IF('IO List'!B4="GVL",CONCATENATE('IO List'!A4),"") | C4: =IF('IO List'!B4="GVL",CONCATENATE("AT %",'IO List'!C4),"") | D4: =IF('IO List'!B4="GVL",CONCATENATE(": ",'IO List'!D4,";"),"") | E4: =IF('IO List'!B4="GVL",CONCATENATE("// ",'IO List'!F4),"")
B5: =IF('IO List'!B5="GVL",CONCATENATE('IO List'!A5),"") | C5: =IF('IO List'!B5="GVL",CONCATENATE("AT %",'IO List'!C5),"") | D5: =IF('IO List'!B5="GVL",CONCATENATE(": ",'IO List'!D5,";"),"") | E5: =IF('IO List'!B5="GVL",CONCATENATE("// ",'IO List'!F5),"")
B6: =IF('IO List'!B6="GVL",CONCATENATE('IO List'!A6),"") -> SOP700_S2 | C6: =IF('IO List'!B6="GVL",CONCATENATE("AT %",'IO List'!C6),"") -> AT %MX0.1 | D6: =IF('IO List'!B6="GVL",CONCATENATE(": ",'IO List'!D6,";"),"") -> : BOOL; | E6: =IF('IO List'!B6="GVL",CONCATENATE("// ",'IO List'!F6),"") -> // Control Voltage Off (NC)
B7: =IF('IO List'!B7="GVL",CONCATENATE('IO List'!A7),"") -> SOP700_S3 | C7: =IF('IO List'!B7="GVL",CONCATENATE("AT %",'IO List'!C7),"") -> AT %MX0.2 | D7: =IF('IO List'!B7="GVL",CONCATENATE(": ",'IO List'!D7,";"),"") -> : BOOL; | E7: =IF('IO List'!B7="GVL",CONCATENATE("// ",'IO List'!F7),"") -> // Manual/Auto. True=Automatic. False=Manual
B8: =IF('IO List'!B8="GVL",CONCATENATE('IO List'!A8),"") | C8: =IF('IO List'!B8="GVL",CONCATENATE("AT %",'IO List'!C8),"") | D8: =IF('IO List'!B8="GVL",CONCATENATE(": ",'IO List'!D8,";"),"") | E8: =IF('IO List'!B8="GVL",CONCATENATE("// ",'IO List'!F8),"")
B9: =IF('IO List'!B9="GVL",CONCATENATE('IO List'!A9),"") -> SOP700_S5 | C9: =IF('IO List'!B9="GVL",CONCATENATE("AT %",'IO List'!C9),"") -> AT %MX0.4 | D9: =IF('IO List'!B9="GVL",CONCATENATE(": ",'IO List'!D9,";"),"") -> : BOOL; | E9: =IF('IO List'!B9="GVL",CONCATENATE("// ",'IO List'!F9),"") -> // Cycle Start
B10: =IF('IO List'!B10="GVL",CONCATENATE('IO List'!A10),"") -> SOP700_S6 | C10: =IF('IO List'!B10="GVL",CONCATENATE("AT %",'IO List'!C10),"") -> AT %MX0.5 | D10: =IF('IO List'!B10="GVL",CONCATENATE(": ",'IO List'!D10,";"),"") -> : BOOL; | E10: =IF('IO List'!B10="GVL",CONCATENATE("// ",'IO List'!F10),"") -> // Cycle Stop
B11: =IF('IO List'!B11="GVL",CONCATENATE('IO List'!A11),"") -> SOP700_S11 | C11: =IF('IO List'!B11="GVL",CONCATENATE("AT %",'IO List'!C11),"") -> AT %MX0.6 | D11: =IF('IO List'!B11="GVL",CONCATENATE(": ",'IO List'!D11,";"),"") -> : BOOL; | E11: =IF('IO List'!B11="GVL",CONCATENATE("// ",'IO List'!F11),"") -> // Entry Request
B12: =IF('IO List'!B12="GVL",CONCATENATE('IO List'!A12),"") -> SOP700_S8 | C12: =IF('IO List'!B12="GVL",CONCATENATE("AT %",'IO List'!C12),"") -> AT %MX0.7 | D12: =IF('IO List'!B12="GVL",CONCATENATE(": ",'IO List'!D12,";"),"") -> : BOOL; | E12: =IF('IO List'!B12="GVL",CONCATENATE("// ",'IO List'!F12),"") -> // Reset Alarm
B13: =IF('IO List'!B13="GVL",CONCATENATE('IO List'!A13),"") | C13: =IF('IO List'!B13="GVL",CONCATENATE("AT %",'IO List'!C13),"") | D13: =IF('IO List'!B13="GVL",CONCATENATE(": ",'IO List'!D13,";"),"") | E13: =IF('IO List'!B13="GVL",CONCATENATE("// ",'IO List'!F13),"")
B14: =IF('IO List'!B14="GVL",CONCATENATE('IO List'!A14),"") -> SOP700_S7 | C14: =IF('IO List'!B14="GVL",CONCATENATE("AT %",'IO List'!C14),"") -> AT %MX1.1 | D14: =IF('IO List'!B14="GVL",CONCATENATE(": ",'IO List'!D14,";"),"") -> : BOOL; | E14: =IF('IO List'!B14="GVL",CONCATENATE("// ",'IO List'!F14),"") -> // Halt (NC)
B15: =IF('IO List'!B15="GVL",CONCATENATE('IO List'!A15),"") | C15: =IF('IO List'!B15="GVL",CONCATENATE("AT %",'IO List'!C15),"") | D15: =IF('IO List'!B15="GVL",CONCATENATE(": ",'IO List'!D15,";"),"") | E15: =IF('IO List'!B15="GVL",CONCATENATE("// ",'IO List'!F15),"")
... B293: =IF('IO List'!B293="GVL",CONCATENATE('IO List'!A293),"") | C293: =IF('IO List'!B293="GVL",CONCATENATE("AT %",'IO List'!C293),"") | D293: =IF('IO List'!B293="GVL",CONCATENATE(": ",'IO List'!D293,";"),"") | E293: =IF('IO List'!B293="GVL",CONCATENATE("// ",'IO List'!F293),"")

Sheet RobotStudio
A1: Autogenerated configuration for RobotStudio OPC UA Client configuration
A2: Copy into configuration .csv file and delete all empty rows.
A3: NamespaceUri | B3: IdentifierType | C3: Identifier | D3: ReadWrite | E3: Signal | F3: SignalType | G3: Controller | H3: Device | J3: Colum used for identifier generation
A4: =IF(CoDeSysIOs!C4=""," ","CODESYSSPV3/3S/IecVarAccess") | B4: =IF(CoDeSysIOs!C4=""," ","String") | C4: =IF(CoDeSysIOs!C4=""," ",J4&""&E4) | D4: =IF(CoDeSysIOs!B4="","",CoDeSysIOs!H4) | E4: =IF(CoDeSysIOs!C4=""," ",CoDeSysIOs!B4) | F4: =IF(CoDeSysIOs!D4="","",CoDeSysIOs!G4) | J4: |var|CODESYS Control Win V3 x64.Application.IOs.
A5: =IF(CoDeSysIOs!C5=""," ","CODESYSSPV3/3S/IecVarAccess") -> CODESYSSPV3/3S/IecVarAccess | B5: =IF(CoDeSysIOs!C5=""," ","String") -> String | C5: =IF(CoDeSysIOs!C5=""," ",J5&""&E5) -> |var|CODESYS Control Win V3 x64.Application.IOs.SOP700_S1 | D5: =IF(CoDeSysIOs!B5="","",CoDeSysIOs!H5) -> Write | E5: =IF(CoDeSysIOs!C5=""," ",CoDeSysIOs!B5) -> SOP700_S1 | F5: =IF(CoDeSysIOs!D5="","",CoDeSysIOs!G5) -> Digital | J5: |var|CODESYS Control Win V3 x64.Application.IOs.
A6: =IF(CoDeSysIOs!C6=""," ","CODESYSSPV3/3S/IecVarAccess") | B6: =IF(CoDeSysIOs!C6=""," ","String") | C6: =IF(CoDeSysIOs!C6=""," ",J6&""&E6) | D6: =IF(CoDeSysIOs!B6="","",CoDeSysIOs!H6) | E6: =IF(CoDeSysIOs!C6=""," ",CoDeSysIOs!B6) | F6: =IF(CoDeSysIOs!D6="","",CoDeSysIOs!G6) | J6: |var|CODESYS Control Win V3 x64.Application.IOs.
A7: =IF(CoDeSysIOs!C7=""," ","CODESYSSPV3/3S/IecVarAccess") | B7: =IF(CoDeSysIOs!C7=""," ","String") | C7: =IF(CoDeSysIOs!C7=""," ",J7&""&E7) | D7: =IF(CoDeSysIOs!B7="","",CoDeSysIOs!H7) | E7: =IF(CoDeSysIOs!C7=""," ",CoDeSysIOs!B7) | F7: =IF(CoDeSysIOs!D7="","",CoDeSysIOs!G7) | J7: |var|CODESYS Control Win V3 x64.Application.IOs.
A8: =IF(CoDeSysIOs!C8=""," ","CODESYSSPV3/3S/IecVarAccess") | B8: =IF(CoDeSysIOs!C8=""," ","String") | C8: =IF(CoDeSysIOs!C8=""," ",J8&""&E8) | D8: =IF(CoDeSysIOs!B8="","",CoDeSysIOs!H8) | E8: =IF(CoDeSysIOs!C8=""," ",CoDeSysIOs!B8) | F8: =IF(CoDeSysIOs!D8="","",CoDeSysIOs!G8) | J8: |var|CODESYS Control Win V3 x64.Application.IOs.
A9: =IF(CoDeSysIOs!C9=""," ","CODESYSSPV3/3S/IecVarAccess") | B9: =IF(CoDeSysIOs!C9=""," ","String") | C9: =IF(CoDeSysIOs!C9=""," ",J9&""&E9) | D9: =IF(CoDeSysIOs!B9="","",CoDeSysIOs!H9) | E9: =IF(CoDeSysIOs!C9=""," ",CoDeSysIOs!B9) | F9: =IF(CoDeSysIOs!D9="","",CoDeSysIOs!G9) | J9: |var|CODESYS Control Win V3 x64.Application.IOs.
A10: =IF(CoDeSysIOs!C10=""," ","CODESYSSPV3/3S/IecVarAccess") | B10: =IF(CoDeSysIOs!C10=""," ","String") | C10: =IF(CoDeSysIOs!C10=""," ",J10&""&E10) | D10: =IF(CoDeSysIOs!B10="","",CoDeSysIOs!H10) | E10: =IF(CoDeSysIOs!C10=""," ",CoDeSysIOs!B10) | F10: =IF(CoDeSysIOs!D10="","",CoDeSysIOs!G10) | J10: |var|CODESYS Control Win V3 x64.Application.IOs.
A11: =IF(CoDeSysIOs!C11=""," ","CODESYSSPV3/3S/IecVarAccess") | B11: =IF(CoDeSysIOs!C11=""," ","String") | C11: =IF(CoDeSysIOs!C11=""," ",J11&""&E11) | D11: =IF(CoDeSysIOs!B11="","",CoDeSysIOs!H11) | E11: =IF(CoDeSysIOs!C11=""," ",CoDeSysIOs!B11) | F11: =IF(CoDeSysIOs!D11="","",CoDeSysIOs!G11) | J11: |var|CODESYS Control Win V3 x64.Application.IOs.
A12: =IF(CoDeSysIOs!C12=""," ","CODESYSSPV3/3S/IecVarAccess") | B12: =IF(CoDeSysIOs!C12=""," ","String") | C12: =IF(CoDeSysIOs!C12=""," ",J12&""&E12) | D12: =IF(CoDeSysIOs!B12="","",CoDeSysIOs!H12) | E12: =IF(CoDeSysIOs!C12=""," ",CoDeSysIOs!B12) | F12: =IF(CoDeSysIOs!D12="","",CoDeSysIOs!G12) | J12: |var|CODESYS Control Win V3 x64.Application.IOs.
A13: =IF(CoDeSysIOs!C13=""," ","CODESYSSPV3/3S/IecVarAccess") | B13: =IF(CoDeSysIOs!C13=""," ","String") | C13: =IF(CoDeSysIOs!C13=""," ",J13&""&E13) | D13: =IF(CoDeSysIOs!B13="","",CoDeSysIOs!H13) | E13: =IF(CoDeSysIOs!C13=""," ",CoDeSysIOs!B13) | F13: =IF(CoDeSysIOs!D13="","",CoDeSysIOs!G13) | J13: |var|CODESYS Control Win V3 x64.Application.IOs.
A14: =IF(CoDeSysIOs!C14=""," ","CODESYSSPV3/3S/IecVarAccess") | B14: =IF(CoDeSysIOs!C14=""," ","String") | C14: =IF(CoDeSysIOs!C14=""," ",J14&""&E14) | D14: =IF(CoDeSysIOs!B14="","",CoDeSysIOs!H14) | E14: =IF(CoDeSysIOs!C14=""," ",CoDeSysIOs!B14) | F14: =IF(CoDeSysIOs!D14="","",CoDeSysIOs!G14) | J14: |var|CODESYS Control Win V3 x64.Application.IOs.
A15: =IF(CoDeSysIOs!C15=""," ","CODESYSSPV3/3S/IecVarAccess") -> CODESYSSPV3/3S/IecVarAccess | B15: =IF(CoDeSysIOs!C15=""," ","String") -> String | C15: =IF(CoDeSysIOs!C15=""," ",J15&""&E15) -> |var|CODESYS Control Win V3 x64.Application.IOs.SOP700_NS1 | D15: =IF(CoDeSysIOs!B15="","",CoDeSysIOs!H15) -> Write | E15: =IF(CoDeSysIOs!C15=""," ",CoDeSysIOs!B15) -> SOP700_NS1 | F15: =IF(CoDeSysIOs!D15="","",CoDeSysIOs!G15) -> Digital | J15: |var|CODESYS Control Win V3 x64.Application.IOs.
... A300: =IF(CoDeSysIOs!C300=""," ","CODESYSSPV3/3S/IecVarAccess") | B300: =IF(CoDeSysIOs!C300=""," ","String") | C300: =IF(CoDeSysIOs!C300=""," ",J300&""&E300) | D300: =IF(CoDeSysIOs!B300="","",CoDeSysIOs!H300) | E300: =IF(CoDeSysIOs!C300=""," ",CoDeSysIOs!B300) | F300: =IF(CoDeSysIOs!D300="","",CoDeSysIOs!G300) | J300: |var|CODESYS Control Win V3 x64.Application.IOs.
